Workbook

Sheet 2026 (Year VI Current Season)
A1: Trager * | C1: Jowkar | E1: Delaney | G1: Green | I1: Berke * | J1: 2026 | N1: 2025-26 Fantasy Season | P1: 10/21/25 - 3/22/26 | R1: "The Offseason" : 2026 | T1: (N/A)
E2: 1st Round Delaney | N2: BERK Berke 2030 2nd round | O2: FOR | P2: JOWK Noah Clowney
E3: 1st Round Peterson** (2026 Jowkar FRP owns swap rights) | O3: 45953
E4: 1st Round Green
E5: 2nd Round Delaney | N5: GOLD Neemias Queta | O5: FOR | P5: TRAG Ayo Dosumnu
E6: 2nd Round Trager | O6: 45647
E7: 2nd Round Green
A8: 2026 | N8: PETE Steph Curry | O8: FOR | P8: TRAG Miles Bridges
A9: Gold | C9: Moss * | E9: Baden | G9: Peterson ** | I9: Zujewski | N9: PETE Kawhi Leonard | O9: 46062 | P9: TRAG Bilal Couliably
A10: 1st Round Gold (Trager 2026 FRP owns swap rights) | E10: 1st Round Baden | G10: 1st Round Trager (right to swap with Gold 2026 FRP) | I10: 1st Round Zujewski | P10: TRAG Berke 2026 1st round
E11: 1st Round Jowkar * (owns 2026 Peterson FRP swap rights) | G11: 1st Round Berke | I11: 1st Round Moss | P11: TRAG Trager 2028 1st round
E12: 2nd Round Baden | G12: 2nd Round Gold | I12: 2nd Round Peterson | P12: TRAG Gold 2026 2nd round
E13: 2nd Round Zujewski | G13: 2nd Round Moss | P13: TRAG Gold 2029 2nd round
E14: 2nd Round Berke
E15: 2nd Round Jowkar | J15: Constitution
A16: Draft Pick Protections | H16: Protected Pick
A17: * If Kelvin is lower pick, swap with Jowkar | H17: Locked Pick- Future Protection/swap
A18: ** If Kelvin is higher pick, no swap | H18: Green (*) - Conveyed from past protection
A52: G-league: | C52: 1st call up - Oct 20th 2025 | E52: 2nd call up - Nov 23rd 2025 | G52: 3rd call up - Jan 5th, 2025 | I52: 4th call up - Feb 9th 2026 (Monday)
A53: Trager | C53: Carter Bryant | E53: Carter Bryant | G53: Carter Bryant | I53: Carter Bryant
C54: Tijaun Salaun | E54: Hugo Gonzalez | G54: Hugo Gonzalez | I54: Hugo Gonzalez
A55: Jowkar | C55: Kasparas Jakucionis | E55: Kasparas Jakucionis | G55: Kasparas Jakucionis | I55: Nikola Jovic
C56: Nikola Jovic | E56: Nikola Jovic | G56: Asa Newall | I56: Asa Newall
A57: Delaney | C57: Joan Beringer | E57: Joan Beringer | G57: Joan Beringer | I57: Joan Beringer
C58: Yang Hansen | E58: Yang Hansen | G58: Yang Hansen | I58: Yang Hansen
A59: Green | C59: Rasheer Fleming | E59: Rasheer Fleming | G59: Ryan Dunn | I59: Ryan Dunn
C60: GG Jackson | E60: GG Jackson | G60: GG Jackson | I60: Will Riley
A61: Berke | C61: Kam Jones | E61: Kam Jones | G61: Kam Jones | I61: Kam Jones
A63: Gold | C63: Anthony Black | E63: Cam Whitmore | G63: Cam Whitmore | I63: Cam Whitmore
C64: Noa Essengue | E64: Noa Essengue | G64: Noa Essengue | I64: Noa Essengue
A65: Moss | C65: Ron Holland | E65: Ron Holland | G65: Ron Holland | I65: Ron Holland
C66: Adem Bona | E66: Adem Bona | G66: Adem Bona | I66: Adem Bona
A67: Baden | C67: Rob Dillingham | E67: Bub Carrington | G67: Bub Carrington | I67: Bub Carrington
C68: Dereck Lively | E68: Dereck Lively | G68: Dereck Lively | I68: Dereck Lively
A69: Peterson | C69: Devin Carter | E69: Devin Carter | G69: Devin Carter | I69: Devin Carter
C70: Thomas Sorber | E70: Thomas Sorber | G70: Thomas Sorber | I70: Thomas Sorber
A71: Zujewski | C71: Jeremiah Fears | E71: Sion James | G71: Sion James | I71: Sion James
C72: Liam McNeeley | E72: Liam McNeeley | G72: Liam McNeeley | I72: Liam McNeeley

Sheet 2025 (Last Season)
A1: Trager | C1: Jowkar | E1: Delaney | G1: Green | I1: Berke | J1: 2025 | O1: 2024-25 Fantasy Season | S1: "The Offseason" : 2025 | U1: (N/A)
A2: 2nd Round Zujewski | C2: 2nd Round Moss | E2: 1st Round Delaney* (right to swap w/Jowkar 2025 FRP) | O2: ZJEW Wendall Carter Jr. | P2: FOR | Q2: PETE Peterson 2026 2nd round | S2: BERK Spencer Dinwiddie | T2: FOR | U2: JOWK Jerami Grant
A3: 2nd Round Gold (Jowkar 2025 2nd owns swap rights) | E3: 1st Round Berke (Peterson 2025 1st owns swap rights) | P3: 45525 | Q3: PETE Peterson 2027 2nd round | T3: 45853 | U3: JOWK Jrue Holiday
A4: 2nd Round Kelley | E4: 1st Round Green
E5: 2nd Round Green (right to swap w/Trager 2025 SRP) | O5: KELL Kelley 2025 2nd round | P5: FOR | Q5: JOWK Gold 2027 2nd round | S5: BADEN Berke 2025 1st round | T5: FOR | U5: DELA Peterson 2025 1st round
E6: 2nd Round Berke (Peterson 2025 2nd owns swap rights) | P6: 45560 | Q6: JOWK Gold 2028 2nd round | S6: BADEN Green 2025 1st round | T6: 45863 | U6: DELA Baden 2025 2nd round
E7: 2nd Round Delaney
A8: 2025 | O8: KELL Mikal Bridges | P8: FOR | Q8: PETE Jowkar 2026 1st round | S8: July 26th, 2025
A9: Gold | C9: Moss | E9: Kelley -> Baden | G9: Peterson | I9: Zujewski | O9: KELL Moss 2026 2nd round | Q9: PETE Peterson 2025 2nd round | S9: / / / / / / / / / Draft Day 2025 / / / / / / / / /
A10: 1st Round Gold | E10: 1st Round Kelley | G10: 2nd Round Jowkar (right to swap w/Gold 2025 SRP) | I10: 1st Round Zujewski | P10: 45587 | Q10: PETE Zujewski 2026 2nd round | S10: TRAG Berke 2027 1st round | T10: FOR | U10: BADEN Baden 2025 2nd round
E11: 1st Round Jowkar* (Delaney 2025 1st owns swap rights) | I11: 1st Round Moss | T11: 45864 | U11: BADEN Gold 2025 2nd round
E12: 1st Round Peterson (right to swap w/Berke 2025 1st round) | I12: 1st Round Trager | O12: TRAG Mark Williams | P12: FOR | Q12: GOLD Ivica Zubac | U12: BADEN Gold 2026 2nd round
E13: 2nd Round Peterson (right to swap w/Berke 2025 2nd) | I13: 2nd Round Trager** (Green 2025 2nd owns swap rights) | O13: TRAG Andrew Nembhard | P13: 45594 | Q13: GOLD Gold 2029 2nd round
S14: TRAG Daniel Gafford | T14: FOR | U14: GOLD Gold 2030 2nd round
O15: GREEN Joel Embiid | P15: FOR | Q15: MOSS Bam Adebayo | T15: 45865
A16: Draft Pick Protections | H16: Protected Pick | J16: Constitution | O16: GREEN Green 2029 1st round | P16: 45603
A17: * Swap rights to the owner of Delaney 2025 FRP | H17: Locked Pick- Future Protection
A18: Choose between higher of Delaney 2025 FRP and Jowkar 2025 FRP | H18: Green (*) - Conveyed from past protection | O18: DELA Bobby Portis | P18: FOR | Q18: PETE Zujewski 2027 2nd round
P19: 45656
A20: ** Swap rights to the owner of Green 2025 SRP | I20: Top 2 Scorers Matched up That Week
A21: Choose between higher of Trager 2025 SRP and Green 2025 SRP - if swap doesn't occur, conveys in 2026 | I21: Week | J21: 1st | K21: MOV | L21: 2nd | M21: 3rd | O21: PETE Mikal Bridges | P21: FOR | Q21: BERK James Harden
I22: 1 | J22: Green | K22: 13 | L22: Jowkar | M22: Zujewski | O22: PETE Berke 2027 2nd round | P22: 45679
I23: 2 | J23: Jowkar | K23: 140 | L23: Kelvin | M23: Logan
A24: 2025 Draft Order: | C24: 1st Rd Owner (Rookies) | E24: 2nd Rd Owner (Rookie & FA) | G24: 3rd Rd Owner Comp Round | I24: 3 | J24: Jowkar | K24: 223 | L24: Logan | M24: Kelvin | O24: BERK Paul George | P24: FOR | Q24: JOWK Zach Lavine
A25: #1: Lottery #1 (40% Baden) | C25: Baden | E25: Delaney | G25: Baden | I25: 4 | J25: Jowkar | K25: 93 | L25: Logan | M25: Max | O25: BERK Bradley Beal
A26: #2: Lottery #2 (30% Delaney) | C26: Zujewski | E26: Delaney | G26: Delaney | I26: 5 | J26: Logan | K26: 93 | L26: Kelvin | M26: Jowkar | O26: BERK Jrue Holiday
A27: #3: Lottery #3 (20% Gold) | C27: Delaney | E27: Peterson | G27: Gold | I27: 6 | J27: Jowkar | K27: 113 | L27: Kelvin | M27: Trager | O27: BERK Berke 2027 2nd round | P27: 45683
A28: #4: Lottery #4 (10% Zujewski) | C28: Gold | E28: Trager | G28: Zujewski | I28: 7 | J28: Green | K28: 85 | L28: Jowkar | M28: Trager
A29: #5: Moss | C29: Zujewski | E29: Jowkar | G29: Moss | I29: 8 | J29: Jowkar | K29: 52 | L29: Trager | M29: Green | O29: TRAG Coby White | P29: FOR | Q29: ZJEW Jamal Murray
A30: #6: Berke | C30: Delaney | E30: Baden | G30: Berke | I30: 9 | J30: Jowkar | K30: 53 | L30: Moss | M30: Trager | O30: TRAG Nicolas Claxton
A31: #7: Peterson | C31: Baden | E31: Delaney | G31: Peterson | I31: 10 | J31: Jowkar | K31: =112+144 -> 256 | L31: Max | M31: Trager | O31: TRAG Trager 2025 1st round | P31: 45686
A32: #8: Green | C32: Baden | E32: Delaney | G32: Green | I32: 11 | J32: Jowkar | K32: 5 | L32: Green | M32: Trager
A33: #9: Jowkar | C33: Baden | E33: Baden | G33: Jowkar | I33: 12 | J33: Trager | K33: 200 | L33: Zujewski | M33: Logan | O33: TRAG Yves Missi | P33: FOR | Q33: KELL Daniel Gafford
A34: #10: Trager | C34: Zujewski | E34: Zujewski | G34: Trager | I34: 13 | J34: Green | K34: 176 | L34: Trager | M34: Kelvin | O34: TRAG Jowkar 2026 2nd round | P34: 45698
I35: 14 | J35: Jowkar | K35: 11 | L35: Kelvin | M35: Trager
I36: 15 | J36: Green | K36: 225 | L36: Trager | M36: Moss | O36: TRAG Jordan Poole | P36: FOR | Q36: KELL Kristaps Porzingus
I37: 16 | J37: Trager | K37: 224 | L37: Green | M37: Zujewski | O37: TRAG Berke 2025 1st round | P37: 45698
A39: Punishments: | G39: 1st place finishes | I39: 2nd place finishes | K39: 3rd place finishes | M39: Total | O39: JOWK Kelley 2025 2nd round | P39: FOR | Q39: DELA John Collins
A40: Strike 1: | B40: ! | C40: Warning | G40: Logan | H40: =COUNTIF($J$21:$J$38, G40) -> 1 | I40: Logan | J40: =COUNTIF($L$21:$L$38,I40) -> 2 | K40: Logan | L40: =COUNTIF($M$21:$M$38,K40) -> 2 | M40: =H40+J40+L40 -> 5 | O40: JOWK Jowkar 2028 2nd round | P40: 45698
A41: Strike 2: | B41: !! | C41: Warning #2 | G41: Kelvin | H41: =COUNTIF($J$21:$J$38, G41) -> 0 | I41: Kelvin | J41: =COUNTIF($L$21:$L$38,I41) -> 4 | K41: Kelvin | L41: =COUNTIF($M$21:$M$38,K41) -> 2 | M41: =H41+J41+L41 -> 6
...

Sheet 2027
A1: Trager | C1: Jowkar | E1: Delaney | G1: Green | I1: Berke | J1: 2027 | N1: 2026-27 Fantasy Season | R1: "The Offseason" : 2026 | T1: (N/A)
A2: 1st Round Trager (right to swap w/Baden 2027 FRP*) | C2: 1st Round Delaney | E2: 1st Round Peterson | G2: 1st Round Green | O2: FOR
A3: 2nd Round Trager | C3: 2nd Round Berke | E3: 2nd Round Delaney
E4: 2nd Round Zujewski
A8: 2027
A9: Gold | C9: Moss | E9: Baden | G9: Peterson | I9: Zujewski
A10: 1st Round Gold | C10: 1st Round Moss (Baden 2027 FRP owns swap rights) | E10: 1st Round Baden* (Trager 2027 FRP owns swap rights) (right to swap w/Moss 2027 FRP) | I10: 1st Round Zujewski
E11: 1st Round Jowkar | I11: 2nd Round Peterson
E12: 1st Round Berke
E13: 2nd Round Baden
E14: 2nd Round Jowkar
E15: 2nd Round Moss | J15: Constitution
A16: Draft Pick Protections | E16: 2nd Round Green | H16: Protected Pick
A17: * Protected Top 3, conveys to Baden 2028 FRP if it doesn't convey | E17: 2nd Round Gold | H17: Locked Pick- Future Protection/swap
H18: Swap rights

Sheet 2028
A1: Trager | C1: Jowkar | E1: Delaney | G1: Green | I1: Berke | J1: 2028 | N1: 2026-27 Fantasy Season | R1: "The Offseason" : 2026 | T1: (N/A)
A2: 2nd Round Trager | C2: 1st Round Jowkar | E2: 1st Round Delaney | G2: 1st Round Green | O2: FOR
C3: 2nd Round Berke | E3: 1st Round Berke | G3: 2nd Round Green
E4: 2nd Round Delaney
E5: 2nd Round Jowkar
A8: 2028
A9: Gold | C9: Moss | E9: Baden | G9: Peterson | I9: Zujewski
A10: 1st Round Gold | E10: 1st Round Baden* | G10: 1st Round Peterson | I10: 1st Round Zujewski
E11: 1st Round Moss | G11: 1st Round Trager | I11: 2nd Round Zujewski
E12: 2nd Round Moss | G12: 2nd Round Peterson
E13: 2nd Round Kelley
E14: 2nd Round Gold
J15: Constitution
A16: Draft Pick Protections | H16: Protected Pick
A17: * Conveys to Trager if Kelley 2027 FRP swap connected to Trager FRP becomes 1-3 | H17: Locked Pick- Future Protection/swap
A18: *Conveys to Moss if Kelley 2027 FRP swap connected to Trager FRP becomes 4-10 | H18: Green (*) - Conveyed from past protection

Sheet 2029
A1: Trager | C1: Jowkar | E1: Delaney | G1: Green | I1: Berke | J1: 2029 | N1: 2026-27 Fantasy Season | R1: "The Offseason" : 2026 | T1: (N/A)
A2: 1st Round Trager | C2: 1st Round Jowkar | E2: 1st Round Delaney | G2: 2nd Round Green | O2: FOR
A3: 2nd Round Trager | C3: 2nd Round Jowkar | E3: 2nd Round Delaney
C4: 2nd Round Berke
A8: 2029
A9: Gold | C9: Moss | E9: Baden | G9: Peterson | I9: Zujewski
A10: 1st Round Gold | C10: 1st Round Moss | E10: 1st Round Baden* | G10: 1st Round Peterson | I10: 1st Round Zujewski
C11: 1st Round Green | E11: 2nd Round Baden | G11: 1st Round Berke | I11: 2nd Round Zujewski
C12: 2nd Round Moss | G12: 2nd Round Peterson
G13: 2nd Round Gold
J15: Constitution
A16: Draft Pick Protections | H16: Protected Pick
A17: * Conveys to Moss if Baden 2027 FRP swap connected to Trager FRP becomes 1-3 | H17: Locked Pick- Future Protection/swap
H18: Green (*) - Conveyed from past protection

Sheet 2030
A1: Trager | C1: Jowkar | E1: Delaney | G1: Green | I1: Berke | J1: 2030 | N1: 2029-30 Fantasy Season | R1: "The Offseason" : 2030 | T1: (N/A)
A2: 1st Round Trager | C2: 1st Round Jowkar | E2: 1st Round Delaney | G2: 1st Round Green | I2: 1st Round Berke | O2: FOR
A3: 2nd Round Trager | C3: 2nd Round Jowkar | E3: 2nd Round Delaney | G3: 2nd Round Green
A4: 2nd Round Gold | C4: 2nd Round Berke
A8: 2030
A9: Gold | C9: Moss | E9: Baden | G9: Peterson | I9: Zujewski
A10: 1st Round Gold | C10: 1st Round Moss | E10: 1st Round Baden | G10: 1st Round Peterson | I10: 1st Round Zujewski
C11: 2nd Round Moss | E11: 2nd Round Baden | G11: 2nd Round Peterson | I11: 2nd Round Zujewski
A16: Draft Pick Protections | H16: Protected Pick
H17: Locked Pick- Future Protection/swap
H18: Green (*) - Conveyed from past protection

Sheet All Picks (26-30)
B2: Twin Towers | C2: Ball Don't Lie | D2: Washed Kings | E2: Ice Trae | F2: Logan | G2: Giddey Up | H2: Pure Sweat Fam | I2: Flaming Flaggs | J2: Droppin Dimes | K2: Only Franz
A3: 2026 | B3: {=INDIRECT("'2026 (Year VI: Current Season)'!A2")} | C3: {=INDIRECT("'2026 (Year VI: Current Season)'!C2")} | D3: {=INDIRECT("'2026 (Year VI: Current Season)'!E2")} -> 1st Round Delaney | E3: {=INDIRECT("'2026 (Year VI: Current Season)'!G2")} | F3: {=INDIRECT("'2026 (Year VI: Current Season)'!I2")} | G3: {=INDIRECT("'2026 (Year VI: Current Season)'!A10")} -> 1st Round Gold (Trager 2026 FRP owns swap rights) | H3: {=INDIRECT("'2026 (Year VI: Current Season)'!C10")} | I3: {=INDIRECT("'2026 (Year VI: Current Season)'!E10")} -> 1st Round Baden | J3: {=INDIRECT("'2026 (Year VI: Current Season)'!G10")} -> 1st Round Trager (right to swap with Gold 2026 FRP) | K3: {=INDIRECT("'2026 (Year VI: Current Season)'!I10")} -> 1st Round Zujewski
B4: {=INDIRECT("'2026 (Year VI: Current Season)'!A3")} | C4: {=INDIRECT("'2026 (Year VI: Current Season)'!C3")} | D4: {=INDIRECT("'2026 (Year VI: Current Season)'!E3")} -> 1st Round Peterson** (2026 Jowkar FRP owns swap rights) | E4: {=INDIRECT("'2026 (Year VI: Current Season)'!G3")} | F4: {=INDIRECT("'2026 (Year VI: Current Season)'!I3")} | G4: {=INDIRECT("'2026 (Year VI: Current Season)'!A11")} | H4: {=INDIRECT("'2026 (Year VI: Current Season)'!C11")} | I4: {=INDIRECT("'2026 (Year VI: Current Season)'!E11")} -> 1st Round Jowkar * (owns 2026 Peterson FRP swap rights) | J4: {=INDIRECT("'2026 (Year VI: Current Season)'!G11")} -> 1st Round Berke | K4: {=INDIRECT("'2026 (Year VI: Current Season)'!I11")} -> 1st Round Moss
B5: {=INDIRECT("'2026 (Year VI: Current Season)'!A4")} | C5: {=INDIRECT("'2026 (Year VI: Current Season)'!C4")} | D5: {=INDIRECT("'2026 (Year VI: Current Season)'!E4")} -> 1st Round Green | E5: {=INDIRECT("'2026 (Year VI: Current Season)'!G4")} | F5: {=INDIRECT("'2026 (Year VI: Current Season)'!I4")} | G5: {=INDIRECT("'2026 (Year VI: Current Season)'!A12")} | H5: {=INDIRECT("'2026 (Year VI: Current Season)'!C12")} | I5: {=INDIRECT("'2026 (Year VI: Current Season)'!E12")} -> 2nd Round Baden | J5: {=INDIRECT("'2026 (Year VI: Current Season)'!G12")} -> 2nd Round Gold | K5: {=INDIRECT("'2026 (Year VI: Current Season)'!I12")} -> 2nd Round Peterson
B6: {=INDIRECT("'2026 (Year VI: Current Season)'!A5")} | C6: {=INDIRECT("'2026 (Year VI: Current Season)'!C5")} | D6: {=INDIRECT("'2026 (Year VI: Current Season)'!E5")} -> 2nd Round Delaney | E6: {=INDIRECT("'2026 (Year VI: Current Season)'!G5")} | F6: {=INDIRECT("'2026 (Year VI: Current Season)'!I5")} | G6: {=INDIRECT("'2026 (Year VI: Current Season)'!A13")} | H6: {=INDIRECT("'2026 (Year VI: Current Season)'!C13")} | I6: {=INDIRECT("'2026 (Year VI: Current Season)'!E13")} -> 2nd Round Zujewski | J6: {=INDIRECT("'2026 (Year VI: Current Season)'!G13")} -> 2nd Round Moss | K6: {=INDIRECT("'2026 (Year VI: Current Season)'!I13")}
B7: {=INDIRECT("'2026 (Year VI: Current Season)'!A6")} | C7: {=INDIRECT("'2026 (Year VI: Current Season)'!C6")} | D7: {=INDIRECT("'2026 (Year VI: Current Season)'!E6")} -> 2nd Round Trager | E7: {=INDIRECT("'2026 (Year VI: Current Season)'!G6")} | F7: {=INDIRECT("'2026 (Year VI: Current Season)'!I6")} | G7: {=INDIRECT("'2026 (Year VI: Current Season)'!A14")} | H7: {=INDIRECT("'2026 (Year VI: Current Season)'!C14")} | I7: {=INDIRECT("'2026 (Year VI: Current Season)'!E14")} -> 2nd Round Berke | J7: {=INDIRECT("'2026 (Year VI: Current Season)'!G14")} | K7: {=INDIRECT("'2026 (Year VI: Current Season)'!I14")}
B8: {=INDIRECT("'2026 (Year VI: Current Season)'!A7")} | C8: {=INDIRECT("'2026 (Year VI: Current Season)'!C7")} | D8: {=INDIRECT("'2026 (Year VI: Current Season)'!E7")} -> 2nd Round Green | E8: {=INDIRECT("'2026 (Year VI: Current Season)'!G7")} | F8: {=INDIRECT("'2026 (Year VI: Current Season)'!I7")} | G8: {=INDIRECT("'2026 (Year VI: Current Season)'!A15")} | H8: {=INDIRECT("'2026 (Year VI: Current Season)'!C15")} | I8: {=INDIRECT("'2026 (Year VI: Current Season)'!E15")} -> 2nd Round Jowkar | J8: {=INDIRECT("'2026 (Year VI: Current Season)'!G15")} | K8: {=INDIRECT("'2026 (Year VI: Current Season)'!I15")}
A9: 2027 | B9: {=INDIRECT("'2027'!A2")} -> 1st Round Trager (right to swap w/Baden 2027 FRP*) | C9: {=INDIRECT("'2027'!C2")} -> 1st Round Delaney | D9: {=INDIRECT("'2027'!E2")} -> 1st Round Peterson | E9: {=INDIRECT("'2027'!G2")} -> 1st Round Green | F9: {=INDIRECT("'2027'!I2")} | G9: {=INDIRECT("'2027'!A10")} -> 1st Round Gold | H9: {=INDIRECT("'2027'!C10")} -> 1st Round Moss (Baden 2027 FRP owns swap rights) | I9: {=INDIRECT("'2027'!E10")} -> 1st Round Baden* (Trager 2027 FRP owns swap rights) (right to swap w/Moss 2027 FRP) | J9: {=INDIRECT("'2027'!G10")} | K9: {=INDIRECT("'2027'!I10")} -> 1st Round Zujewski
B10: {=INDIRECT("'2027'!A3")} -> 2nd Round Trager | C10: {=INDIRECT("'2027'!C3")} -> 2nd Round Berke | D10: {=INDIRECT("'2027'!E3")} -> 2nd Round Delaney | E10: {=INDIRECT("'2027'!G3")} | F10: {=INDIRECT("'2027'!I3")} | G10: {=INDIRECT("'2027'!A11")} | H10: {=INDIRECT("'2027'!C11")} | I10: {=INDIRECT("'2027'!E11")} -> 1st Round Jowkar | J10: {=INDIRECT("'2027'!G11")} | K10: {=INDIRECT("'2027'!I11")} -> 2nd Round Peterson
B11: {=INDIRECT("'2027'!A4")} | C11: {=INDIRECT("'2027'!C4")} | D11: {=INDIRECT("'2027'!E4")} -> 2nd Round Zujewski | E11: {=INDIRECT("'2027'!G4")} | F11: {=INDIRECT("'2027'!I4")} | G11: {=INDIRECT("'2027'!A12")} | H11: {=INDIRECT("'2027'!C12")} | I11: {=INDIRECT("'2027'!E12")} -> 1st Round Berke | J11: {=INDIRECT("'2027'!G12")} | K11: {=INDIRECT("'2027'!I12")}
B12: {=INDIRECT("'2027'!A5")} | C12: {=INDIRECT("'2027'!C5")} | D12: {=INDIRECT("'2027'!E5")} | E12: {=INDIRECT("'2027'!G5")} | F12: {=INDIRECT("'2027'!I5")} | G12: {=INDIRECT("'2027'!A13")} | H12: {=INDIRECT("'2027'!C13")} | I12: {=INDIRECT("'2027'!E13")} -> 2nd Round Baden | J12: {=INDIRECT("'2027'!G13")} | K12: {=INDIRECT("'2027'!I13")}
B13: {=INDIRECT("'2027'!A6")} | C13: {=INDIRECT("'2027'!C6")} | D13: {=INDIRECT("'2027'!E6")} | E13: {=INDIRECT("'2027'!G6")} | F13: {=INDIRECT("'2027'!I6")} | G13: {=INDIRECT("'2027'!A14")} | H13: {=INDIRECT("'2027'!C14")} | I13: {=INDIRECT("'2027'!E14")} -> 2nd Round Jowkar | J13: {=INDIRECT("'2027'!G14")} | K13: {=INDIRECT("'2027'!I14")}
B14: {=INDIRECT("'2027'!A7")} | C14: {=INDIRECT("'2027'!C7")} | D14: {=INDIRECT("'2027'!E7")} | E14: {=INDIRECT("'2027'!G7")} | F14: {=INDIRECT("'2027'!I7")} | G14: {=INDIRECT("'2027'!A15")} | H14: {=INDIRECT("'2027'!C15")} | I14: {=INDIRECT("'2027'!E15")} -> 2nd Round Moss | J14: {=INDIRECT("'2027'!G15")} | K14: {=INDIRECT("'2027'!I15")}
I15: {=INDIRECT("'2027'!E16")} -> 2nd Round Green
I16: {=INDIRECT("'2027'!E17")} -> 2nd Round Gold
A17: 2028 | B17: {=INDIRECT("'2028'!A2")} -> 2nd Round Trager | C17: {=INDIRECT("'2028'!C2")} -> 1st Round Jowkar | D17: {=INDIRECT("'2028'!E2")} -> 1st Round Delaney | E17: {=INDIRECT("'2028'!G2")} -> 1st Round Green | F17: {=INDIRECT("'2028'!I2")} | G17: {=INDIRECT("'2028'!A10")} -> 1st Round Gold | H17: {=INDIRECT("'2028'!C10")} | I17: {=INDIRECT("'2028'!E10")} -> 1st Round Baden* | J17: {=INDIRECT("'2028'!G10")} -> 1st Round Peterson | K17: {=INDIRECT("'2028'!I10")} -> 1st Round Zujewski
B18: {=INDIRECT("'2028'!A3")} | C18: {=INDIRECT("'2028'!C3")} -> 2nd Round Berke | D18: {=INDIRECT("'2028'!E3")} -> 1st Round Berke | E18: {=INDIRECT("'2028'!G3")} -> 2nd Round Green | F18: {=INDIRECT("'2028'!I3")} | G18: {=INDIRECT("'2028'!A11")} | H18: {=INDIRECT("'2028'!C11")} | I18: {=INDIRECT("'2028'!E11")} -> 1st Round Moss | J18: {=INDIRECT("'2028'!G11")} -> 1st Round Trager | K18: {=INDIRECT("'2028'!I11")} -> 2nd Round Zujewski
B19: {=INDIRECT("'2028'!A4")} | C19: {=INDIRECT("'2028'!C4")} | D19: {=INDIRECT("'2028'!E4")} -> 2nd Round Delaney | E19: {=INDIRECT("'2028'!G4")} | F19: {=INDIRECT("'2028'!I4")} | G19: {=INDIRECT("'2028'!A12")} | H19: {=INDIRECT("'2028'!C12")} | I19: {=INDIRECT("'2028'!E12")} -> 2nd Round Moss | J19: {=INDIRECT("'2028'!G12")} -> 2nd Round Peterson | K19: {=INDIRECT("'2028'!I12")}
B20: {=INDIRECT("'2028'!A5")} | C20: {=INDIRECT("'2028'!C5")} | D20: {=INDIRECT("'2028'!E5")} -> 2nd Round Jowkar | E20: {=INDIRECT("'2028'!G5")} | F20: {=INDIRECT("'2028'!I5")} | G20: {=INDIRECT("'2028'!A13")} | H20: {=INDIRECT("'2028'!C13")} | I20: {=INDIRECT("'2028'!E13")} -> 2nd Round Kelley | J20: {=INDIRECT("'2028'!G13")} | K20: {=INDIRECT("'2028'!I13")}
B21: {=INDIRECT("'2028'!A6")} | C21: {=INDIRECT("'2028'!C6")} | D21: {=INDIRECT("'2028'!E6")} | E21: {=INDIRECT("'2028'!G6")} | F21: {=INDIRECT("'2028'!I6")} | G21: {=INDIRECT("'2028'!A14")} | H21: {=INDIRECT("'2028'!C14")} | I21: {=INDIRECT("'2028'!E14")} -> 2nd Round Gold | J21: {=INDIRECT("'2028'!G14")} | K21: {=INDIRECT("'2028'!I14")}
B22: {=INDIRECT("'2028'!A7")} | C22: {=INDIRECT("'2028'!C7")} | D22: {=INDIRECT("'2028'!E7")} | E22: {=INDIRECT("'2028'!G7")} | F22: {=INDIRECT("'2028'!I7")} | G22: {=INDIRECT("'2028'!A15")} | H22: {=INDIRECT("'2028'!C15")} | I22: {=INDIRECT("'2028'!E15")} | J22: {=INDIRECT("'2028'!G15")} | K22: {=INDIRECT("'2028'!I15")}
A23: 2029 | B23: {=INDIRECT("'2029'!A2")} -> 1st Round Trager | C23: {=INDIRECT("'2029'!C2")} -> 1st Round Jowkar | D23: {=INDIRECT("'2029'!E2")} -> 1st Round Delaney | E23: {=INDIRECT("'2029'!G2")} -> 2nd Round Green | F23: {=INDIRECT("'2029'!I2")} | G23: {=INDIRECT("'2029'!A10")} -> 1st Round Gold | H23: {=INDIRECT("'2029'!C10")} -> 1st Round Moss | I23: {=INDIRECT("'2029'!E10")} -> 1st Round Baden* | J23: {=INDIRECT("'2029'!G10")} -> 1st Round Peterson | K23: {=INDIRECT("'2029'!I10")} -> 1st Round Zujewski
B24: {=INDIRECT("'2029'!A3")} -> 2nd Round Trager | C24: {=INDIRECT("'2029'!C3")} -> 2nd Round Jowkar | D24: {=INDIRECT("'2029'!E3")} -> 2nd Round Delaney | E24: {=INDIRECT("'2029'!G3")} | F24: {=INDIRECT("'2029'!I3")} | G24: {=INDIRECT("'2029'!A11")} | H24: {=INDIRECT("'2029'!C11")} -> 1st Round Green | I24: {=INDIRECT("'2029'!E11")} -> 2nd Round Baden | J24: {=INDIRECT("'2029'!G11")} -> 1st Round Berke | K24: {=INDIRECT("'2029'!I11")} -> 2nd Round Zujewski
B25: {=INDIRECT("'2029'!A4")} | C25: {=INDIRECT("'2029'!C4")} -> 2nd Round Berke | D25: {=INDIRECT("'2029'!E4")} | E25: {=INDIRECT("'2029'!G4")} | F25: {=INDIRECT("'2029'!I4")} | G25: {=INDIRECT("'2029'!A12")} | H25: {=INDIRECT("'2029'!C12")} -> 2nd Round Moss | I25: {=INDIRECT("'2029'!E12")} | J25: {=INDIRECT("'2029'!G12")} -> 2nd Round Peterson | K25: {=INDIRECT("'2029'!I12")}
B26: {=INDIRECT("'2029'!A5")} | C26: {=INDIRECT("'2029'!C5")} | D26: {=INDIRECT("'2029'!E5")} | E26: {=INDIRECT("'2029'!G5")} | F26: {=INDIRECT("'2029'!I5")} | G26: {=INDIRECT("'2029'!A13")} | H26: {=INDIRECT("'2029'!C13")} | I26: {=INDIRECT("'2029'!E13")} | J26: {=INDIRECT("'2029'!G13")} -> 2nd Round Gold | K26: {=INDIRECT("'2029'!I13")}
B27: {=INDIRECT("'2029'!A6")} | C27: {=INDIRECT("'2029'!C6")} | D27: {=INDIRECT("'2029'!E6")} | E27: {=INDIRECT("'2029'!G6")} | F27: {=INDIRECT("'2029'!I6")} | G27: {=INDIRECT("'2029'!A14")} | H27: {=INDIRECT("'2029'!C14")} | I27: {=INDIRECT("'2029'!E14")} | J27: {=INDIRECT("'2029'!G14")} | K27: {=INDIRECT("'2029'!I14")}
B28: {=INDIRECT("'2029'!A7")} | C28: {=INDIRECT("'2029'!C7")} | D28: {=INDIRECT("'2029'!E7")} | E28: {=INDIRECT("'2029'!G7")} | F28: {=INDIRECT("'2029'!I7")} | G28: {=INDIRECT("'2029'!A15")} | H28: {=INDIRECT("'2029'!C15")} | I28: {=INDIRECT("'2029'!E15")} | J28: {=INDIRECT("'2029'!G15")} | K28: {=INDIRECT("'2029'!I15")}
A29: 2030 | B29: {=INDIRECT("'2030'!A2")} -> 1st Round Trager | C29: {=INDIRECT("'2030'!C2")} -> 1st Round Jowkar | D29: {=INDIRECT("'2030'!E2")} -> 1st Round Delaney | E29: {=INDIRECT("'2030'!G2")} -> 1st Round Green | F29: {=INDIRECT("'2030'!I2")} -> 1st Round Berke | G29: {=INDIRECT("'2030'!A10")} -> 1st Round Gold | H29: {=INDIRECT("'2030'!C10")} -> 1st Round Moss | I29: {=INDIRECT("'2030'!E10")} -> 1st Round Baden | J29: {=INDIRECT("'2030'!G10")} -> 1st Round Peterson | K29: {=INDIRECT("'2030'!I10")} -> 1st Round Zujewski
B30: {=INDIRECT("'2030'!A3")} -> 2nd Round Trager | C30: {=INDIRECT("'2030'!C3")} -> 2nd Round Jowkar | D30: {=INDIRECT("'2030'!E3")} -> 2nd Round Delaney | E30: {=INDIRECT("'2030'!G3")} -> 2nd Round Green | F30: {=INDIRECT("'2030'!I3")} | G30: {=INDIRECT("'2030'!A11")} | H30: {=INDIRECT("'2030'!C11")} -> 2nd Round Moss | I30: {=INDIRECT("'2030'!E11")} -> 2nd Round Baden | J30: {=INDIRECT("'2030'!G11")} -> 2nd Round Peterson | K30: {=INDIRECT("'2030'!I11")} -> 2nd Round Zujewski
B31: {=INDIRECT("'2030'!A4")} -> 2nd Round Gold | C31: {=INDIRECT("'2030'!C4")} -> 2nd Round Berke | D31: {=INDIRECT("'2030'!E4")} | E31: {=INDIRECT("'2030'!G4")} | F31: {=INDIRECT("'2030'!I4")} | G31: {=INDIRECT("'2030'!A12")} | H31: {=INDIRECT("'2030'!C12")} | I31: {=INDIRECT("'2030'!E12")} | J31: {=INDIRECT("'2030'!G12")} | K31: {=INDIRECT("'2030'!I12")}
B32: {=INDIRECT("'2030'!A5")} | C32: {=INDIRECT("'2030'!C5")} | D32: {=INDIRECT("'2030'!E5")} | E32: {=INDIRECT("'2030'!G5")} | F32: {=INDIRECT("'2030'!I5")} | G32: {=INDIRECT("'2030'!A13")} | H32: {=INDIRECT("'2030'!C13")} | I32: {=INDIRECT("'2030'!E13")} | J32: {=INDIRECT("'2030'!G13")} | K32: {=INDIRECT("'2030'!I13")}
B33: {=INDIRECT("'2030'!A6")} | C33: {=INDIRECT("'2030'!C6")} | D33: {=INDIRECT("'2030'!E6")} | E33: {=INDIRECT("'2030'!G6")} | F33: {=INDIRECT("'2030'!I6")} | G33: {=INDIRECT("'2030'!A14")} | H33: {=INDIRECT("'2030'!C14")} | I33: {=INDIRECT("'2030'!E14")} | J33: {=INDIRECT("'2030'!G14")} | K33: {=INDIRECT("'2030'!I14")}
B34: {=INDIRECT("'2030'!A7")} | C34: {=INDIRECT("'2030'!C7")} | D34: {=INDIRECT("'2030'!E7")} | E34: {=INDIRECT("'2030'!G7")} | F34: {=INDIRECT("'2030'!I7")} | G34: {=INDIRECT("'2030'!A15")} | H34: {=INDIRECT("'2030'!C15")} | I34: {=INDIRECT("'2030'!E15")} | J34: {=INDIRECT("'2030'!G15")} | K34: {=INDIRECT("'2030'!I15")}
B37: Twin Towers | C37: Ball Don't Lie | D37: Washed Kings | E37: Ice Trae | F37: Logan | G37: Giddey Up | H37: Pure Sweat Fam | I37: Flaming Flaggs | J37: Droppin Dimes | K37: Only Franz
A38: 1st Round Picks | B38: =SUM(COUNTIF(B3:B34, "*1st Round*")) -> 3 | C38: =SUM(COUNTIF(C3:C34, "*1st Round*")) -> 4 | D38: =SUM(COUNTIF(D3:D34, "*1st Round*")) -> 8 | E38: =SUM(COUNTIF(E3:E34, "*1st Round*")) -> 3 | F38: =SUM(COUNTIF(F3:F34, "*1st Round*")) -> 1 | G38: =SUM(COUNTIF(G3:G34, "*1st Round*")) -> 5 | H38: =SUM(COUNTIF(H3:H34, "*1st Round*")) -> 4 | I38: =SUM(COUNTIF(I3:I34, "*1st Round*")) -> 9 | ... K38: =SUM(COUNTIF(K3:K34, "*1st Round*")) -> 6
A39: 2nd Round Picks | B39: =SUM(COUNTIF(B3:B34, "*2nd Round*")) -> 5 | C39: =SUM(COUNTIF(C3:C34, "*2nd Round*")) -> 6 | D39: =SUM(COUNTIF(D3:D34, "*2nd Round*")) -> 9 | E39: =SUM(COUNTIF(E3:E34, "*2nd Round*")) -> 3 | F39: =SUM(COUNTIF(F3:F34, "*2nd Round*")) -> 0 | G39: =SUM(COUNTIF(G3:G34, "*2nd Round*")) -> 0 | H39: =SUM(COUNTIF(H3:H34, "*2nd Round*")) -> 2 | I39: =SUM(COUNTIF(I3:I34, "*2nd Round*")) -> 14 | ... K39: =SUM(COUNTIF(K3:K34, "*2nd Round*")) -> 5
A40: Total Picks | B40: =COUNTA(B3:B34) -> 8 | C40: =COUNTA(C3:C34) -> 10 | D40: =COUNTA(D3:D34) -> 17 | E40: =COUNTA(E3:E34) -> 6 | F40: =COUNTA(F3:F34) -> 1 | G40: =COUNTA(G3:G34) -> 5 | H40: =COUNTA(H3:H34) -> 6 | I40: =COUNTA(I3:I34) -> 23 | ... K40: =COUNTA(K3:K34) -> 11

Sheet 2031
A1: Trager | C1: Jowkar | E1: Delaney | G1: Green | I1: Berke | J1: 2031 | N1: 2030-31 Fantasy Season | R1: "The Offseason" : 2031 | T1: (N/A)
A2: 1st Round Trager | C2: 1st Round Jowkar | E2: 1st Round Delaney | G2: 1st Round Green | I2: 1st Round Berke | O2: FOR
A3: 2nd Round Trager | C3: 2nd Round Jowkar | E3: 2nd Round Delaney | G3: 2nd Round Green | I3: 2nd Round Berke
A8: 2031
A9: Gold | C9: Moss | E9: Baden | G9: Peterson | I9: Zujewski
A10: 1st Round Gold | C10: 1st Round Moss | E10: 1st Round Baden | G10: 1st Round Peterson | I10: 1st Round Zujewski
A11: 2nd Round Gold | C11: 2nd Round Moss | E11: 2nd Round Baden | G11: 2nd Round Peterson | I11: 2nd Round Zujewski
A16: Draft Pick Protections | H16: Protected Pick
H17: Locked Pick- Future Protection/swap
H18: Green (*) - Conveyed from past protection

Sheet League Records
B2: Min 24000 | C2: Min 25000
E3: Most Points In a Day
A4: Rank | B4: Most Points For In a Season | C4: Most Points Against In a Season | D4: Most Points in a Week | E4: Date | F4: Team | G4: Score | H4: Most Top 50 Points Days
A5: 1 | B5: Kelvin - 34645 (2022-23) | C5: Green - 28338 (2021-22) | D5: Kelvin - 2437 (23-24 Week 12) | E5: 46009 | F5: Jowkar | G5: 544 | H5: Kelvin | I5: =COUNTIF(F5:F54, "Kelvin") -> 15
A6: 2 | B6: Kelvin - 31260 (2023-24) | C6: Kelvin - 27752 (2021-22) | D6: Kelvin - 2430 (22-23 Week 14) | E6: 3/11/23 | F6: Logan | G6: 510 | H6: Logan | I6: =COUNTIF(F5:F54, "Logan") -> 9
A7: 3 | B7: Moss - 30725 (2022-23) | C7: Spencer - 27534 (2021-22) | D7: Kelvin - 2416 (22-23 Week 12) | E7: 45252 | F7: Jowkar | G7: 503 | H7: Moss | I7: =COUNTIF(F5:F54, "Moss") -> 7
A8: 4 | B8: Kelvin - 30042 (2021-22) | C8: Zujewski - 27301 (2021-22) | D8: Kelvin - 2401 (22-23 Week 16) | E8: 12/14/22 | F8: Kelvin | G8: 501 | H8: Jowkar | I8: =COUNTIF(F5:F54, "Jowkar") -> 11
A9: 5 | B9: Trager - 29711 (2021-22) | C9: Gold - 27275 (2022-23) | D9: Kelvin - 2395 (22-23 Week 13) | E9: 1/2/23 | F9: Delaney | G9: 501 | H9: Trager | I9: =COUNTIF(F5:F54, "Trager") -> 4
A10: 6 | B10: Logan - 29620 (2021-22) | C10: Green - 26967 (2022-23) | D10: Moss - 2346 (22-23 Week 11) | E10: 45253 | F10: Jowkar | G10: 499 | H10: Green | I10: =COUNTIF(F5:F54, "Green") -> 3
A11: 7 | B11: Moss - 29128 (2021-22) | C11: Jowkar - 26914 (2022-23) | D11: Kelvin - 2322 (23-24 Week 8) | E11: 12/18/23 | F11: Green | G11: 495 | H11: Delaney | I11: =COUNTIF(F5:F54, "Delaney") -> 1
A12: 8 | B12: Jowkar - 28877 (2023-24) | C12: Delaney - 26862 (2022-23) | D12: Trager - 2316 (24-25 Week 16) | E12: 1/15/23 | F12: Kelvin | G12: 495 | H12: Kelley | I12: =COUNTIF(F5:F54, "Kelley") -> 0
A13: 9 | B13: Jowkar - 28688 (2024-25) | C13: Trager - 26555 (2022-23) | D13: Jowkar - 2267 (23-24 Week 15) | E13: 3/10/24 | F13: Kelvin | G13: 495 | J13: =SUM(I5:I12) -> 50
A14: 10 | B14: Delaney - 28416 (2022-23) | C14: Spencer - 26500 (2022-23) | D14: Kelvin - 2256 (23-24 Week 10) | E14: 10/30/23 | F14: Kelvin | G14: 493
A15: 11 | B15: Green - 28274 (2024-25) | C15: Logan - 26128 (2022-23) | D15: Kelvin - 2255 (22-23 Week 17) | E15: 45289 | F15: Kelvin | G15: 491
A16: 12 | B16: Green - 28050 (2023-24) | C16: Zujewski - 25667 (2023-24) | D16: Kelvin - 2224 (22-23 Week 11) | E16: 11/6/24 | F16: Jowkar | G16: 487
A17: 13 | B17: Logan - 27782 (2023-24) | C17: Zujewski - 25641 (2022-23) | D17: Green - 2211 (24-25 Week 14) | E17: 2/4/23 | F17: Logan | G17: 483 | H17: Highest single game scoring all time
A18: 14 | B18: Trager - 27702 (2024-25) | C18: Gold - 25154 (2023-24) | D18: Logan - 2206 (23-24 Week 15) | E18: 45294 | F18: Logan | G18: 482
A19: 15 | B19: Kelvin - 26734 (2024-25) | C19: Peterson - 25008 (2024-25) | D19: Kelvin - 2205 (23-24 Week 15) | E19: 45294 | F19: Kelvin | G19: 476 | H19: Player | I19: Score | J19: Date
A20: 16 | B20: Spencer - 26515 (2022-23) | D20: Kelvin - 2201 (23-24 Week 16) | E20: 44191 | F20: Trager | G20: 475
A21: 17 | B21: Logan - 26180 (2022-23) | D21: Kelvin - 2201 (22-23 Week 15) | E21: 44244 | F21: Moss | G21: 474 | H21: Doncic | I21: 119 | J21: 45285
A22: 18 | B22: Logan - 25127 (2024-25) | D22: Moss - 2199 (20-21 Week 14) | E22: 2/4/23 | F22: Kelvin | G22: 473 | H22: Luka | I22: 117 | J22: 45317
A23: 19 | B23: Moss - 24703 (2024-25) | D23: Green - 2166 (23-24 Week 15) | E23: 3/1/24 | F23: Logan | G23: 470 | H23: Embiid | I23: 115 | J23: 44878
A24: 20 | B24: Logan - 24391 (2020-21) | D24: Jowkar - 2155 (24-25 Week 6) | E24: 45352 | F24: Logan | G24: 470 | H24: Doncic | I24: 112 | J24: 44922
A25: 21 | B25: Zujewski - 24273 (2024-25) | D25: Logan - 2150 (21-22 Week 7) | E25: 45260 | F25: Kelvin | G25: 469 | H25: Embiid | I25: 110 | J25: 45313
A26: 22 | B26: Green - 24191 (2022-23) | D26: Jowkar - 2138 (24-25 Week 3) | E26: 45320 | F26: Jowkar | G26: 466 | H26: Giannis | I26: 109 | J26: 45609
A27: 23 | B27: Kelvin - 24115 (2020-21) | D27: Jowkar - 2131 (24-25 Week 2) | E27: 45322 | F27: Logan | G27: 464 | H27: Mitchell | I27: 109 | J27: 44928
A28: 24 | B28: Moss - 24054 (2020-21) | D28: Kelvin - 2128 (23-24 Week 11) | E28: 45303 | F28: Jowkar | G28: 462 | H28: Brunson | I28: 108 | J28: 45275
A29: 25 | D29: Kelvin - 2127 (23-24 Week 13) | E29: 45275 | F29: Green | G29: 461 | H29: Lillard | I29: 108 | J29: 44951
A30: 26 | D30: Logan - 2124 (21-22 Chip Week 1) | E30: 45247 | F30: Logan | G30: 461 | H30: Lillard | I30: 104 | J30: 44983
A31: 27 | D31: Jowkar - 2121 (23-24 Week 8) | E31: 2/25/24 | F31: Jowkar | G31: 461 | H31: Luka | I31: 102 | J31: 44926
A32: 28 | D32: Jowkar - 2112 (24-25 Week 10) | E32: 2/22/24 | F32: Jowkar | G32: 460 | H32: Giannis | I32: 100 | J32: 45273
A33: 29 | D33: Logan - 2109 (23-24 Week 8) | E33: 44555 | F33: Logan | G33: 460
A34: 30 | D34: Kelvin - 2095 (22-23 Week 9) | E34: 11/9/22 | F34: Moss | G34: 460
A35: 31 | D35: Green - 2092 (24-25 Week 16) | E35: 1/16/23 | F35: Kelvin | G35: 460
A36: 32 | D36: Trager - 2087 (24-25 Week 12) | E36: 45621 | F36: Jowkar | G36: 459
A37: 33 | D37: Jowkar - 2082 (23-24 Week 10) | E37: 44284 | F37: Moss | G37: 458
A38: 34 | D38: Jowkar - 2078 (23-24 Week 14) | E38: 12/23/22 | F38: Kelvin | G38: 458
A39: 35 | D39: Jowkar - 2063 (23-24 Week 11) | E39: 44626 | F39: Trager | G39: 456
A40: 36 | D40: Kelvin - 2063 (22-23 Week 3) | E40: 44188 | F40: Moss | G40: 454
A41: 37 | D41: Logan - 2050 (23-24 Week 4) | E41: 11/25/22 | F41: Moss | G41: 453
...

Sheet Offseason Schedule
A1: Dynasty/NBA Event 2025 | B1: Date | D1: Dynasty/NBA Event 2024 | E1: Date | G1: Dynasty/NBA Event 2023 | H1: Date | J1: Dynasty/NBA Event 2022 | K1: Date | M1: Dynasty/NBA Event 2021 | N1: Date
A2: End of Championship Round | B2: March 23rd, 2025 | D2: End of Championship Round | E2: March 24th, 2024 | G2: End of Championship Round | H2: March 26th, 2023 | J2: End of Championship Round | K2: April 10th, 2022 | M2: End of Championship Round | N2: May 16th, 2021
A3: Trading Reopens | B3: March 24th, 2025 | D3: Trading Reopens | E3: March 25th, 2024 | G3: Trading Reopens | H3: March 27th, 2023 | J3: Trading Reopens | K3: April 11th, 2022 | M3: Trading Reopens | N3: May 17th, 2021
A4: Free Agency Locks | B4: March 24th, 2025 | D4: Free Agency Locks | E4: March 25th, 2024 | G4: Free Agency Locks | H4: April 9th, 2023 | J4: Dynasty Draft Lottery Free Agency Locks | K4: April 18th, 2022 | M4: Dynasty Draft Lottery Free Agency Locks | N4: May 23rd, 2021
A5: NBA Lottery | B5: May 12th, 2025 | D5: NBA Lottery | E5: May 12th, 2024 | G5: NBA Lottery | H5: May 16th, 2023 | J5: NBA Lottery | K5: May 17th, 2022 | M5: NBA Lottery | N5: June 22nd, 2021
A6: Dynasty Draft Lottery | B6: March 24th, 2025 | D6: Dynasty Draft Lottery | E6: April 15th, 2024 | G6: Dynasty Draft Lottery | J6: NBA Draft | K6: June 23rd, 2022 | M6: League Meeting #1 | N6: Sometime in July
A7: NBA Draft | B7: June 25th, 2025 | D7: NBA Draft | E7: June 26th, 2024 | G7: NBA Draft | H7: June 22rd, 2023 | J7: NBA Summer League | K7: July 7-17th, 2022 | M7: NBA Draft | N7: July 29th, 2021
A8: NBA Free Agency | B8: June 30th, 2025 | D8: NBA Free Agency | E8: June 30th, 2024 | G8: NBA Free Agency | H8: June 30th, 2023 | J8: NBA Free Agency | K8: August 2nd, 2022 | M8: NBA Free Agency | N8: August 2nd, 2021
A9: NBA Summer League | B9: July 10th-20th, 2025 | D9: NBA Summer League | E9: July 12th-22nd, 2024 | G9: NBA Summer League | H9: July 7-17th, 2023 | J9: Keeper Deadline | K9: August 15th, 2022 | M9: NBA Summer League | N9: August 8th - August 17th, 2021
A10: Keeper Deadline | B10: July 19th, 2025 | D10: Keeper Deadline | E10: July 28th, 2024 | G10: Keeper Deadline | H10: July 30th, 2023 | J10: Dynasty Draft League Meeting | M10: Keeper Deadline | N10: August 16th, 2021
A11: Dynasty Draft League Meeting | D11: Dynasty Draft League Meeting | E11: August 4th, 2024 | G11: Dynasty Draft League Meeting | J11: Start of NBA Training Camps | M11: Dynasty Draft League Meeting #2 | N11: August 29th
A12: Dynasty Draft | B12: July 26th, 2025 | D12: Dynasty Draft | E12: August 4th, 2024 (after league meeting) | G12: Start of NBA Training Camps | J12: Start of NBA Season | K12: October 18th, 2022 | M12: Start of NBA Training Camps | N12: September 28th
A13: Start of NBA Training Camps | D13: Start of NBA Training Camps | E13: September 27th, 2024 | G13: Start of NBA Season | H13: October 24th | J13: NBA All Star Game | K13: 44976 | M13: Start of NBA Season | N13: October 19th
A14: Start of NBA Season | D14: Start of NBA Season | E14: October 22nd, 2024 | G14: 16 regular season weeks (?) | J14: 15 Regular season weeks ends
A15: ___ regular season weeks | D15: 15 regular season weeks | E15: October 22nd, 2024 - Feb 10, 2025 | G15: Play-in Round | H15: Feb 12 - 24, 2024 | J15: Play-in Round | K15: Feb 13 - 26, 2023
A16: NBA Cup double week | D16: NBA Cup double week | E16: December 9 -22, 2024 | G16: Semifinals round | H16: Feb 25 - March 10, 2024 | J16: Semifinals round | K16: Feb 27 - March 12, 2023
A17: Play-in Round | D17: Play-in Round | E17: Feb 10 - 23, 2025 | G17: Championship round | H17: March 11 - 24, 2024 | J17: Chamionship round | K17: Mach 13 - 26, 2023
A18: Semifinals round | D18: Semifinals round | E18: Feb 24 - March 9, 2025 | G18: Playoffs end (according to Lloyd) | H18: 45375 | J18: Playoffs end | K18: March 27th, 2023
A19: Championship round | D19: Championship round | E19: March 10 - 23, 2025 | G19: Regular Season End | H19: 45396 | J19: Regular season ends | K19: April 9th, 2023
A20: Regular season ends | D20: Regular season ends
G21: 1 week back in schedule from last year for start of NBA season
A22: Need to be sure I actually do the NBA cup double week (manual on Fantrax) | D22: Added NBA cup double week | G22: Lloyd suggests 3 weeks before season end. We did 2 weeks last year | J22: May need to discuss 1-2 weeks depending on the all-star game and how it falls that year
A23: Considering changing playoffs timing given NBA starts to sit players | D23: 3 days of rest between games this year makes this easier to have as a double week (2 last year)

Sheet Trades - All Time

Sheet 2024
A1: Twin Towers | C1: Ball Don't Lie | E1: Washed Kings | G1: Ice Trae | I1: Logan | J1: 2024 | N1: 2023-24 Fantasy Season | P1: 10/24/23 - 3/24/23 | T1: "The Offseason" : 2024 | V1: (N/A)
A2: 2nd Round Trager (Owns swap rights w/Jowkar 2024 2nd) | E2: 1st Round Green (right to swap with Berke 2024 1st) | N2: KELL Kelley 2028 1st round | O2: FOR | P2: MOSS Kristaps Porzingus | T2: KELL Kelley 2028 FRP, conveys to Kelley 2029 FRP if Kelley 2027 FRP falls 1-3 in 2027 | U2: FOR | V2: MOSS Moss 2025 2nd round
A3: 2nd Round Jowkar (Trager 2024 2nd owns swap rights) (Owns swap rights w/Kelley 2024 2nd) | E3: 1st Round Delaney | N3: KELL Khris Middleton | O3: 45224
E4: 2nd Round Delaney | N4: KELL Jakob Poeltl | T4: KELL Desmond Bane | U4: FOR | V4: TRAG Trager 2024 1st round
U5: 45469 | V5: TRAG Kelley 2026 1st round
N6: PETE Coby White | O6: FOR | P6: TRAG Delaney 2025 2nd round | V6: TRAG Gold 2025 2nd round
A7: 2024 | O7: 45225
A8: No Shaime | C8: Pure Sweat Fam | E8: BK's Whoppers | G8: Droppin Dimes | I8: Only Franz | T8: DELA Jaylen Brown | U8: FOR | V8: ZJEW Jaime Jaquez
A9: 1st Round Gold (right to swap with Kelley 2024 1st) | C9: 1st Round Peterson | E9: 1st Round Trager | G9: 2nd Round Kelley (Jowkar 2024 2nd owns swap rights) | I9: 1st Round Zujewski | N9: MOSS De'Aaron Fox | O9: FOR | P9: KELL CJ McCollum | T9: DELA Cam Johnson | U9: 45475 | V9: ZJEW Taylor Hendricks
C10: 1st Round Moss*^ | E10: 1st Round Jowkar | G10: 2nd Round Moss | I10: 2nd Round Zujewski | N10: MOSS Bam Adebayo | O10: 45244 | P10: KELL Jonas Valanciunas | V10: ZJEW Delaney 2026 1st round
E11: 1st Round Berke (1st round Green owns swap rights) | I11: 2nd Round Peterson | N11: MOSS Myles Turner | P11: KELL Dario Saric | V11: ZJEW Delaney 2024 2nd round (#16 overall)
E12: 1st Round Kelley (Gold 2024 1st owns swap rights) | N12: MOSS Rudy Gobert | P12: KELL Nicolas Batum | V12: ZJEW Zujewski 2025 2nd round
E13: 2nd Round Green | N13: MOSS Russell Westbrook | P13: KELL Bismack Biyombo
E14: 2nd Round Berke | P14: KELL Jowkar 2024 1st round | T14: PETE Mitchell Robinson | U14: FOR | V14: KELL Clint Capela
E15: 2nd Round Gold | H15: Protected Pick | P15: KELL Kelley 2024 1st round | T15: PETE Berke 2026 2nd round | U15: 45496 | V15: KELL Moss 2024 2nd round (#13 overall)
A16: Draft Pick Protections | H16: Locked Pick- Future Protection/swap | P16: KELL Berke 2024 1st round | T16: PETE Green 2024 2od round (#17 overall)
A17: * top 3 protected - conveys to (locked) pete 2024 frp or moss 2025 frp | H17: Swap rights | P17: KELL Kelley 2025 1st round
A18: ^ swap rights to Pete 2024 FRP | P18: KELL Green 2025 1st round | T18: TRAG Darius Garland | U18: FOR | V18: DELA Devin Booker
I19: Week | J19: 1st | K19: MOV | L19: 2nd | P19: KELL Berke 2024 2nd round | T19: TRAG Keegan Murray | U19: 45498 | V19: DELA Kelley 2024 2nd round (#15 overall)
A20: Kelley receives #11 overall in this draft as a compensatory pick per summer 2023 new owner negotiations | I20: 1 | J20: Kelvin | K20: 309 | L20: Logan | P20: KELL Moss 2024 2nd round | T20: TRAG Delaney 2024 1st round (#6 overall) | V20: DELA Zujewski 2025 2nd round
A21: Kelley has lost #11 overall in this drast as a compensatory pick per league tanking policy | I21: 2 | J21: Kelvin | K21: 34 | L21: Green | T21: TRAG Peterson 2025 1st round right to swap w/Berke 2025 1st round
I22: 3 | J22: Jowkar | K22: 75 | L22: Green | N22: BERK Shai Gilgeous-Alexander | O22: FOR | P22: DELA Kevin Durant | T22: TRAG Lonzo Ball
A23: 2024 Draft Order: | C23: 1st Rd Owner (Rookies) | E23: 2nd Rd Owner (Rookie & FA) | G23: 3rd Rd Owner Comp Round | I23: 4 | J23: Logan | K23: 247 | L23: Kelley | N23: BERK Berke 2028 1st round | O23: 45246 | P23: DELA Demar Derozan
A24: #1: Lottery #1 (40% Gold) | C24: Gold | E24: Kelley | G24: Gold | I24: 5 | J24: Green | K24: 4 | L24: Kelvin | P24: DELA James Harden | T24: KELL Jerami Grant | U24: FOR | V24: JOWK Daniel Gafford
A25: #2: Lottery #2 (30% Zujewski) | C25: Zujewski | E25: Zujewski | G25: Zujewski | I25: 6 | J25: Logan | K25: 236 | L25: Jowkar | P25: DELA Kyrie Irving | T25: KELL Moss 2025 2nd round | U25: 45501
A26: #3: Lottery #3 (20% Moss) | C26: Moss | E26: Peterson | G26: Moss | I26: 7 | J26: Logan | K26: 18 | L26: Kelvin
A27: #4: Lottery #4 (10% Trager) | C27: Kelley | E27: Trager | G27: Trager | I27: 8 | J27: Kelvin | K27: =2322-2121 -> 201 | L27: Jowkar | N27: DELA Bradley Beal | O27: FOR | P27: PETE Peterson 2025 1st round | T27: August 4th 2024
A28: #5: Kelley | C28: Kelley | E28: Trager | G28: Kelley | I28: 9 | J28: Kelvin | K28: =2048-1884 -> 164 | L28: Jowkar | N28: DELA Terry Rozier | O28: 45246 | P28: PETE Peterson 2026 1st round | T28: / / / / / / / / / Draft Day 2024 / / / / / / / / /
A29: #6: Delaney | C29: Delaney | E29: Delaney | G29: Delaney | I29: 10 | J29: Kelvin | K29: =2256-2082 -> 174 | L29: Jowkar | P29: PETE Peterson 2027 1st round
A30: #7: Green | C30: Delaney | E30: Kelley | G30: Green | I30: 11 | J30: Kelvin | K30: =2128-2063 -> 65 | L30: Jowkar | T30: JOWK Donte Divincenzo | U30: FOR | V30: BERK Berke 2029 2nd round
A31: #8: Berke | C31: Kelley | E31: Kelley | G31: Berke | I31: 12 | J31: Kelvin | K31: =2437-1858 -> 579 | L31: Jowkar | N31: DELA Kyle Kuzma | O31: FOR | P31: GREEN Dyson Daniels
A32: #9: Jowkar | C32: Kelley | E32: Peterson | G32: Jowkar | I32: 13 | J32: Kelvin | K32: =2127-1885 -> 242 | L32: Green | N32: DELA Spencer Dinwiddie | O32: 45260 | P32: GREEN Jeremy Sochan | T32: DELA Delaney 2024 1st round (#6 overall) | U32: FOR | V32: KELL Kelley 2024 1st round (#5 overall)
A33: #10: Kelvin | C33: Moss | E33: Zujewski | G33: Kelvin | I33: 14 | J33: Jowkar | K33: =2078-2035 -> 43 | L33: Kelvin | P33: GREEN Green 2026 1st round | T33: DELA Green 2024 1st round (#7 overall) | U33: 45509 | V33: KELL Berke 2024 1st round (#8 overall)
I34: 15 | J34: Jowkar | K34: =2267-2206 -> 61 | L34: Logan | P34: GREEN Green 2025 2nd round | T34: DELA Green 2027 2nd round
I35: 16 | J35: Kelvin | K35: =2201-1850 -> 351 | L35: Jowkar | P35: GREEN Green 2027 2nd round
T36: PETE Clint Capela | U36: FOR | V36: BERK Kawhi Leonard
N37: DELA Klay Thompson | O37: FOR | P37: JOWK Luguentz Dort | T37: PETE Bradley Beal | U37: 45509 | V37: BERK Berke 2029 1st round
A38: Punishments: | I38: 1st place finishes | K38: 2nd place finishes | O38: 45279 | P38: JOWK Green 2026 2nd round | T38: PETE Jrue Holiday
A39: Strike 1: | B39: ! | C39: Warning | I39: Logan | J39: =COUNTIF($J$20:$J$37, I39) -> 3 | K39: Logan | L39: =COUNTIF($L$20:$L$37,K39) -> 2
A40: Strike 2: | B40: !! | C40: Warning #2 | I40: Kelvin | J40: =COUNTIF($J$20:$J$37, I40) -> 9 | K40: Kelvin | L40: =COUNTIF($L$20:$L$37,K40) -> 3 | N40: DELA Shai Gilgeous-Alexander | O40: FOR | P40: GOLD Devin Booker | T40: DELA Delaney 2024 2nd round (#16 overall) | U40: FOR | V40: TRAG Trager 2024 2nd round (#14 overall)
...

Sheet 2023
A1: uce | C1: Jowkar (!) | E1: Delaney (!) | G1: Green | I1: Berke | J1: 2023 | N1: 2022-23 Fantasy Season | P1: 10/18/22 - 2/12/23 | T1: "The Offseason" : 2023 | V1: 2/13/23 - 8/14/23 | X1: 2023 Drops
A2: 1st Round Trager | C2: 1st Round Jowkar | E2: 1st Round Berke | G2: 1st Round Green | I2: 2nd Round Moss | N2: DELA Peterson 2025 1st Round | O2: FOR | P2: JOWK Klay Thompson | R2: 18 Regular Season Trades | T2: KELL Karl Anthony-Towns | U2: FOR | V2: JOWK Michael Porter Jr.
A3: 1st Round Vlandis* (Delaney 2023 1st owns swap rights) | C3: 2nd Round Vlandis | E3: 2nd Round Green | G3: 1st Round Peterson | N3: DELA Jowkar 2023 2nd Round | T3: KELL Jusuf Nurkic | V3: JOWK Cam Thomas | X3: Norman Powell | Y3: Isaac Okoro | Z3: Keon Johnson
A4: 1st Round Zujewski | C4: 2nd Round Gold | G4: 1st Round Delaney** (Right to swap with Vlandis 2023 1st) | V4: JOWK Kris Dunn | X4: TJ McConnell | Y4: Marcus Morris
A5: 2nd Round Zujewski | N5: HALE Brandom Ingram | O5: FOR | P5: BERK Green 2024 1st Round | V5: JOWK Jowkar 2024 1st round | X5: Drew Eubanks | Y5: Christian Koloko | Z5: Larry Nance
N6: HALE Berke 2025 2nd Round | P6: BERK Berke 2026 1st Round | V6: JOWK Berke 2025 1st round | X6: Nick Richard’s | Y6: Brandon Clarke | Z6: Royce O’neale
A7: 2023 (Year III) | P7: BERK Berke 2027 1st Round | V7: JOWK Gold 2026 2nd round | X7: Aaron Nesmith
A8: Gold (!) | C8: Moss | E8: Vlandis | G8: Peterson | I8: Zujewski (!) | V8: JOWK Kelley 2027 2nd round | Z8: JRE
A9: 1st Round Moss | C9: 1st Round Gold | E9: 2nd Round Delaney | G9: 2nd Round Berke | I9: 2nd Round Trager | N9: PETE Paul George | O9: FOR | P9: BERK Dejounte Murray | X9: Ziaire Williams
I10: 2nd Round Jowkar | N10: PETE Jimmy Butler | P10: BERK Jrue Holiday | T10: DELA Pascal Siakam | U10: FOR | V10: JOWK Berke 2023 1st round (#6 overall) | X10: Malik Beasley | Y10: Killian Hayes | Z10: NAW
I11: 2nd Round Peterson | N11: PETE Tobias Harris | P11: BERK Bones Hyland | V11: JOWK Peterson 2025 1st round | X11: Blake Wesley | Y11: Jonathan Isaac
P12: BERK Collin Sexton | V12: JOWK Jowkar 2023 2nd round (#13 overall) | X12: Ochai Agbaji | Y12: Isaiah Jackson | Z12: Marvin Bagley (Bagels)
V13: JOWK Moses Moody | X13: Jordan Nowara
A14: Draft Pick Protections | N14: PETE Jarred Vanderbilt | O14: FOR | P14: GREEN Nicolas Claxton | X14: Jalen Smith | Y14: Josh Richardson | Z14: Isaiah Hartenstein
H15: Protected Pick | T15: TRAG John Collins | U15: FOR | V15: DELA Peterson 2025 1st round | X15: John Wall
A16: * Swap rights w/Delaney FRP, swap if Vlandis FRP is higher pick | H16: Locked Pick- Future Protection | N16: GOLD Kristaps Porzingis | O16: FOR | P16: MOSS Moss 2023 1st round | T16: TRAG Green 2023 2nd round (#14 overall) | V16: DELA Jowkar 2023 2nd round (#13 overall) | Y16: Lu Dort
A17: ** Swap rights w/Vlandis FRP, swap if Vlandis FRP is higher pick | H17: Green (*) - Conveyed from past protection | P17: MOSS Vlandis 2024 1st round | X17: Jevon Carter | Y17: Santi Aldama
P18: MOSS Moss 2024 2nd round | T18: PETE Nicholas Claxton | U18: FOR | V18: TRAG Peterson 2025 1st round | X18: John Konchar | Y18: Bol Bol
I19: Week | J19: 1st | K19: MOV | L19: 2nd | T19: PETE Delaney 2025 2nd round | V19: TRAG Trager 2026 1st round | X19: Mo Wagner | Y19: Jalen McDaniels
A20: 2023 Draft Order: | C20: 1st Rd Owner | E20: 2nd Rd Owner | G20: 3rd Rd Owner Compensatory Round | I20: 1 | J20: Delaney | K20: 41 | L20: Kelvin | N20: JOWK De'Andre Hunter | O20: FOR | P20: VLAND Vlandis 2027 2nd round | V20: TRAG Kelley 2023 2nd round (#19 overall) | X20: Saddiq Bey | Y20: Isaiah Joe
A21: #1: Lottery #1 (40% Trager) | C21: Jowkar | E21: Trager | G21: Trager | I21: 2 | J21: Delaney | K21: 32 | L21: Kelvin | X21: Doug McDermott | Y21: Tyty Washington
A22: #2: Lottery #2 (30% Jowkar) | C22: Green | E22: Trager | G22: Jowkar | I22: 3 | J22: Delaney | K22: 93 | L22: Kelvin | N22: MOSS Brandon Clarke | O22: FOR | P22: GOLD Kyle Anderson | T22: PETE Derrick White | U22: FOR | V22: JOWK Jusuf Nurkic | X22: Davion Mitchell
A23: #3: Lottery #3 (30% Green) | C23: Trager | E23: Delaney | G23: Green | I23: 4 | J23: Moss | K23: 225 | L23: Kelvin | T23: PETE Kelley 2023 2nd round (#19 overall) | V23: JOWK Berke 2023 2nd round (#17 overall) | X23: Corey Kispert | Y23: Dillon Brooks
A24: #4 Gold | C24: Moss | E24: Kelley | G24: Gold | I24: 5 | J24: Kelvin | K24: 80 | L24: Moss | N24: HALE Marcus Smart | O24: FOR | P24: PETE Green 2023 2nd round | Y24: Jaylen Nowell
A25: #5: Zujewski | C25: Zujewski | E25: Trager | G25: Zujewski | I25: 6 | J25: Moss | K25: 222 | L25: Kelvin | N25: HALE Will Barton | P25: PETE Jowkar 2024 2nd round swap rights (connected to Trager 2024 SRP) | T25: GOLD Kyle Kuzma | U25: FOR | V25: DELA Green 2024 1st round | X25: Caleb Martin | Y25: Chris Duarte
A26: #6: Berke | C26: Delaney | E26: Peterson | G26: Berke | I26: 7 | J26: Kelvin | K26: 157 | L26: Green | T26: GOLD Tyus Jones | V26: DELA Green 2023 2nd round (#14 overall) | X26: Trey Lyles | Y26: Darius Bazley
A27: #7: Delaney | C27: Kelley | E27: Green | G27: Delaney | I27: 8 | J27: Moss | K27: 157 | L27: Kelvin | N27: Kelvin Receives | P27: Trager Receives | R27: Jowkar Receives | T27: GOLD Cole Anthony | X27: Tre Mann | Y27: Xavier Tillman
A28: #8: Vlandis/Kelley | C28: Trager | E28: Jowkar | G28: Kelley | I28: 9 | J28: Kelvin | K28: 107 | L28: Moss | N28: JOWK Buddy Hield | P28: PETE KJ Martin | R28: PETE Berke 2023 2nd round
A29: #9: Moss | C29: Gold | E29: Berke | G29: Moss | I29: 10 | J29: Kelvin | K29: 254 | L29: Delaney | R29: HALE Green 2026 2nd round | T29: Kelley Receives | V29: Gold Recieves | X29: Green receives | Z29: Trager receives
A30: #10: Kelvin | C30: Kelley | E30: Zujewski | G30: Kelvin | I30: 11 | J30: Moss | K30: 122 | L30: Kelvin | T30: GREEN Mikal Bridges | V30: GREEN Jalen Duren | X30: KELL Jalen Brunson | Z30: KELL Berke 2025 1st round
A31: #11: Compensatory | C31: Kelley | I31: 12 | J31: Kelvin | K31: 397 | L31: Delaney | N31: VLAND Gold 2023 2nd round | O31: FOR | P31: BERK Kelly Oubre Jr. | T31: GREEN Delaney 2023 1st round (#7 overall) | V31: KELL Green 2024 1st round receives right to swap with Berke 2024 1st round | X31: KELL Donovan Mitchell | Z31: KELL swap rights to Kelley 2027 1st round (connected to Trager 2027 1st round, top 3 protected, convey to Kelley 2028 1st round)
I32: 13 | J32: Kelvin | K32: 326 | L32: Spencer | N32: VLAND Moss 2023 2nd round | T32: GREEN Peterson 2023 1st round (#10 overall) | V32: KELL Gold 2024 1st round receives right to swap with Kelley 2024 1st round | X32: KELL Delaney 2023 2nd round (#18 overall)
I33: 14 | J33: Kelvin | K33: 507 | L33: Trager | N33: VLAND De'Andre Hunter | T33: GREEN Berke 2024 1st round
I34: 15 | J34: Kelvin | K34: 271 | L34: Delaney | T34: GOLD Kelley 2024 1st round
I35: 16 | J35: Kelvin | K35: 459 | L35: Logan | N35: DELA Vlandis 2026 1st round | O35: FOR | P35: HALE Green 2024 1st round | T35: GOLD Moss 2024 2nd round
I36: 17 | J36: Kelvin | K36: 534 | L36: Delaney | P36: HALE Jowkar 2026 2nd round | T36: TRAG Kelley 2025 1st round
P37: HALE Trager 2026 2nd round | T37: GREEN Green 2025 1st round
T38: GREEN rescinds top 1 protection of 2024 1st round pick, allows Green 2025 1st round to be traded
A39: Punishments: | I39: 1st place finishes | K39: 2nd place finishes | N39: DELA Wendall Carter Jr. | O39: FOR | P39: ZJEW Kyrie Irving
A40: Strike 1: | B40: ! | C40: Warning | I40: Logan | J40: =COUNTIF($J$20:$J$37, I40) -> 0 | K40: Logan | L40: =COUNTIF($L$20:$L$37,K40) -> 1 | N40: DELA Dennis Smith Jr. | T40: GOLD Cam Johnson | U40: FOR | V40: DELA Delaney 2027 1st round
...

Sheet 2022
A1: Lob Land (HALE) | C1: Herro Ball (NJ) | E1: Washed Kings (DELA) | G1: Ice Trae (MAX) | I1: Magic City Hot Wingz (BERK) | J1: 2022 | N1: 2021-22 Fantasy Season | P1: (08/30/21 - 1/10/22 [TBD]) | T1: "The Offseason" : 2022 (April 11th - August ___) | W1: |
A2: 1st Round Jowkar | C2: 1st Round Green | G2: 1st Round Berke^ | I2: 2nd Round Peterson | N2: BERK Berke 2022 1st Round | O2: FOR | P2: HALE Mitchell Robinson | R2: 17 Regular Season Trades | T2: BERK Gordon Hayward | U2: FOR | V2: JOWK Donte Divencenzo
A3: 2nd Round Gold | C3: 1st Round Trager^^ | G3: 1st Round Vlandis* | N3: BERK Berke 2025 2nd Round | V3: JOWK Peterson 2022 2nd round
A4: 2nd Round Vlandis | C4: 2nd Round Delaney | G4: 2nd Round Green | V4: JOWK Delaney 2024 2nd round
A5: 2nd Round Trager | N5: BERK Fred Vanvleet | O5: FOR | P5: DELA Lebron James
A6: 2nd Round Berke | N6: BERK Montrezl Harrell | P6: DELA Draymond Green | T6: GOLD Gold 2023 1st round | U6: FOR | V6: MOSS Vlandis 2022 1st round (swap rights)
A7: 2022 (Year II) | N7: BERK Berke 2024 1st Round | T7: GOLD Kelvin 2024 1st round | V7: MOSS Kelvin 2022 1st round
A8: Deepwater Suggs (GOLD) | C8: Morey Ball (MOSS) | E8: Charlotte Wobnets (MT) | G8: Always Droppin Dimes (DIME) | I8: Z Man the Juice (Zman) | T8: GOLD Brook Lopez | V8: MOSS Jonathan Kuminga
A9: 1st Round Gold | C9: 2nd Round Moss | E9: 2nd Round Jowkar | I9: 1st Round Zujewski | N9: ZJEW Pascal Siakam | O9: FOR | P9: JOWK Saddiq Bey | T9: GOLD Seth Curry
A10: 1st Round Moss** | I10: 2nd Round Zujewski | N10: ZJEW Kemba Walker | P10: JOWK Kevin Porter Jr.
A11: 1st Round Delaney | N11: ZJEW John Wall | P11: JOWK Aaron Gordon | T11: MOSS Dejounte Murray | U11: FOR | V11: PETE Paul George
A12: 1st Round Peterson | T12: MOSS Moss 2024 FRP top 3 protected w/swap rights on Kelvin FRP - conveys to PETE 2024 FRP or Moss 2025 FRP | U12: 44769 | V12: PETE Rudy Gobert
N13: Kelvin Receives | P13: Zujewski Receives | R13: Gold Receives
N14: GOLD Caris Levert | P14: GOLD Jamal Murray | R14: PETE Jerami Grant | T14: VLAND Green 2022 1st round (#4 overall) | U14: FOR | V14: JOWK Caris Levert
A15: Draft Pick Protections & Swaps | H15: Protected Pick | N15: ZJEW Mo Bamba | P15: PETE Chris Duarte | R15: ZJEW Josh Giddey | T15: VLAND Vlandis 2023 2nd round | V15: JOWK Saddiq Bey
A16: * - (Moss owns swap rights, swap if Vlandis is higher pick) | H16: Locked Pick- Future Protection | N16: GOLD Gold 2024 2nd Round | P16: PETE Mason Plumlee | R16: PETE Kelvin 2024 FRP
A17: **- (Swap with Vlandis if Vlandis is higher pick) | H17: Green (*) - Conveyed from past protection | N17: ZJEW Bobby Portis | T17: DELA Fred VanVleet | U17: FOR | V17: PETE Dejounte Murray
T18: DELA D'Angelo Russell | V18: PETE Wendall Carter Jr
A19: ^ - (Trager owns swap rights, swap if Trager is higher pick) | I19: Week | J19: Winner | K19: Victory Margin | L19: 2nd place | N19: DELA Terry Rozier | O19: FOR | P19: JOWK D'Angelo Russell | T19: DELA Nikola Vucevic | V19: PETE Bobby Portis
A20: ^^ - (Swap with Berke FRP if Berke is higher pick) | I20: 1 | J20: Logan | K20: 2 | L20: Moss | N20: DELA Delaney 2022 1st Round | T20: DELA Delaney 2025 2nd round | V20: PETE Gold 2024 2nd round
I21: 2 | J21: Kelvin | K21: 33 | L21: Moss | N21: DELA Berke 2024 1st Round
I22: 3 | J22: Kelvin | K22: 241 | L22: Logan | T22: TRAG Cj McCollum | U22: FOR | V22: VLAND Jowkar 2022 1st round (#5 overall)
A23: 2022 Draft Order: | C23: 1st Rd Owner | E23: 2nd Rd Owner | G23: 3rd Rd Owner Compensatory Round | I23: 4 | J23: Kelvin | K23: 167 | L23: Delaney | N23: JOWK Tyler Herro | O23: FOR | P23: VLAND Lamelo Ball | V23: VLAND Vlandis 2025 1st round
A24: #1: Lottery #1 (40% Gold) | C24: Zujewski | E24: Trager | G24: Gold | I24: 5 | J24: Kelvin | K24: 184 | L24: Delaney | N24: JOWK Jaren Jackson Jr. | P24: VLAND Nassir Little
A25: #2: Lottery #2 (30% Zujewski) | C25: Gold | E25: ZUjewski | G25: Zujewski | I25: 6 | J25: Logan | K25: 29 | L25: Kelvin | N25: JOWK Jakob Poeltl | T25: JOWK 2023 Green 2nd round | U25: FOR | V25: GREEN De'andre Hunter
A26: #3: Lottery #3 (30% Moss via Vlandis) | C26: Gold | E26: Trager | G26: Vlandis | I26: 7 | J26: Trager | K26: 227 | L26: Delaney | N26: JOWK Delaney 2022 1st Round
A27: #4: Green | C27: Jowkar | E27: Green | G27: Green | I27: 8 | J27: Green | K27: 5 | L27: Logan | N27: JOWK Delaney 2023 2nd Round | T27: JOWK Jae'Sean Tate | U27: FOR | V27: VLAND Malik Beasley
A28: #5: Jowkar | C28: Trager | E28: Vlandis | G28: Jowkar | I28: 9 | J28: Trager | K28: 30 | L28: Jowkar | T28: JOWK Gordon Hayward | V28: VLAND Jowkar 2025 1st round
A29: #6: Moss | C29: Green | E29: Moss | G29: Moss | I29: 10 | J29: Logan | K29: 123 | L29: Moss | N29: PETE Caris Levert | O29: FOR | P29: JOWK Dennis Schroeder | T29: JOWK Alex Caruso | V29: VLAND Vlandis 2023 2nd round
A30: #7: Delaney | C30: Gold | E30: Jowkar | G30: Delaney | I30: 11 | J30: Logan | K30: 234 | L30: Green | N30: PETE 2026 Jowkar FRP Swap w/Kelvin 2026 FRP (if swap doesn't happen, protection is Kelvin 2026 SRP) | P30: JOWK Jordan Clarkson | V30: VLAND Vlandis 2026 2nd round
A31: #8: Kelvin | C31: Gold | E31: Berke | G31: Kelvin | I31: 12 | J31: Moss | K31: 15 | L31: Green | N31: PETE Jae Crowder
A32: #9: Trager | C32: Jowkar | E32: Trager | G32: Trager | I32: 13 | J32: Trager | K32: 6 | L32: Green | T32: JOWK Jusuf Nurkic | U32: FOR | V32: VLAND Reggie Jackson
A33: #10: Berke | C33: Green | E33: Trager | G33: Berke | I33: 14 | J33: Kelvin | K33: 240 | L33: Green | N33: JOWK Delaney 2023 1st round | O33: FOR | P33: GREEN Bradley Beal | V33: VLAND Jowkar 2023 1st round
I34: 15 | J34: Moss | K34: 23 | L34: Green | N34: JOWK Berke 2024 1st round | P34: GREEN Jusuf Nurkic | V34: VLAND Vlandis 2026 1st round
I35: 16 | J35: Delaney | K35: 12 | L35: Kelvin | N35: JOWK Berke 2022 2nd round
I36: 17 | J36: Delaney | K36: 46 | L36: Jowkar | N36: JOWK Nassir Little | T36: VLAND Vlandis 2022 2nd round (#13 overall) | U36: FOR | V36: TRAG Mo Bamba
I37: 18 | J37: Trager | K37: 114 | L37: Kelvin | N37: JOWK Nicolas Claxton | T37: VLAND Vlandis 2024 2nd round | V37: TRAG Trager 2022 2nd round (#19 overall)
N39: BERK Harrison Barnes | O39: FOR | P39: PETE Jordan Clarkson | T39: VLAND Tyler Herro | U39: FOR | V39: MOSS Jonas Valanciunas
